<?xml version="1.0" ?>
<!-- =================================================================================== -->
<!-- |    This document was autogenerated by xacro from full_reflex_model.urdf.xacro   | -->
<!-- |    EDITING THIS FILE BY HAND IS NOT RECOMMENDED                                 | -->
<!-- =================================================================================== -->
<robot name="rhr_flex_model" xmlns:xacro="http://www.ros.org/wiki/xacro">
  <!-- ################ ################ ################ ################ ################ ################ -->
  <!-- ################ XACRO PORTION OF THE URDF, FOR MAKING THE FLEXIBLE JOINTS ################ -->
  <!-- ################ ################ ################ ################ ################ ################ -->
  <!-- Macro to make each park of the link -->
  <!-- Macro to one flex body link to the next -->
  <!-- Macro to make the joint from proximal to first link and from last link to distal  -->
  <link name="finger[1]/flex_link[1]">
    <visual>
      <geometry>
        <box size="0.00222222222222 0.014 0.006"/>
      </geometry>
      <material name="dark gray">
        <color rgba="0.2 0.2 .2 1"/>
      </material>
    </visual>
  </link>
  <link name="finger[1]/flex_link[2]">
    <visual>
      <geometry>
        <box size="0.00222222222222 0.014 0.006"/>
      </geometry>
      <material name="dark gray">
        <color rgba="0.2 0.2 .2 1"/>
      </material>
    </visual>
  </link>
  <link name="finger[1]/flex_link[3]">
    <visual>
      <geometry>
        <box size="0.00222222222222 0.014 0.006"/>
      </geometry>
      <material name="dark gray">
        <color rgba="0.2 0.2 .2 1"/>
      </material>
    </visual>
  </link>
  <link name="finger[1]/flex_link[4]">
    <visual>
      <geometry>
        <box size="0.00222222222222 0.014 0.006"/>
      </geometry>
      <material name="dark gray">
        <color rgba="0.2 0.2 .2 1"/>
      </material>
    </visual>
  </link>
  <link name="finger[1]/flex_link[5]">
    <visual>
      <geometry>
        <box size="0.00222222222222 0.014 0.006"/>
      </geometry>
      <material name="dark gray">
        <color rgba="0.2 0.2 .2 1"/>
      </material>
    </visual>
  </link>
  <link name="finger[1]/flex_link[6]">
    <visual>
      <geometry>
        <box size="0.00222222222222 0.014 0.006"/>
      </geometry>
      <material name="dark gray">
        <color rgba="0.2 0.2 .2 1"/>
      </material>
    </visual>
  </link>
  <link name="finger[1]/flex_link[7]">
    <visual>
      <geometry>
        <box size="0.00222222222222 0.014 0.006"/>
      </geometry>
      <material name="dark gray">
        <color rgba="0.2 0.2 .2 1"/>
      </material>
    </visual>
  </link>
  <link name="finger[1]/flex_link[8]">
    <visual>
      <geometry>
        <box size="0.00222222222222 0.014 0.006"/>
      </geometry>
      <material name="dark gray">
        <color rgba="0.2 0.2 .2 1"/>
      </material>
    </visual>
  </link>
  <link name="finger[1]/flex_link[9]">
    <visual>
      <geometry>
        <box size="0.00222222222222 0.014 0.006"/>
      </geometry>
      <material name="dark gray">
        <color rgba="0.2 0.2 .2 1"/>
      </material>
    </visual>
  </link>
  <joint name="finger[1]/flex_joint_from_1_to_2" type="continuous">
    <parent link="finger[1]/flex_link[1]"/>
    <child link="finger[1]/flex_link[2]"/>
    <origin xyz="0.00177777777778 0 0"/>
    <axis xyz="0 -1 0"/>
  </joint>
  <joint name="finger[1]/flex_joint_from_2_to_3" type="continuous">
    <parent link="finger[1]/flex_link[2]"/>
    <child link="finger[1]/flex_link[3]"/>
    <origin xyz="0.00177777777778 0 0"/>
    <axis xyz="0 -1 0"/>
  </joint>
  <joint name="finger[1]/flex_joint_from_3_to_4" type="continuous">
    <parent link="finger[1]/flex_link[3]"/>
    <child link="finger[1]/flex_link[4]"/>
    <origin xyz="0.00177777777778 0 0"/>
    <axis xyz="0 -1 0"/>
  </joint>
  <joint name="finger[1]/flex_joint_from_4_to_5" type="continuous">
    <parent link="finger[1]/flex_link[4]"/>
    <child link="finger[1]/flex_link[5]"/>
    <origin xyz="0.00177777777778 0 0"/>
    <axis xyz="0 -1 0"/>
  </joint>
  <joint name="finger[1]/flex_joint_from_5_to_6" type="continuous">
    <parent link="finger[1]/flex_link[5]"/>
    <child link="finger[1]/flex_link[6]"/>
    <origin xyz="0.00177777777778 0 0"/>
    <axis xyz="0 -1 0"/>
  </joint>
  <joint name="finger[1]/flex_joint_from_6_to_7" type="continuous">
    <parent link="finger[1]/flex_link[6]"/>
    <child link="finger[1]/flex_link[7]"/>
    <origin xyz="0.00177777777778 0 0"/>
    <axis xyz="0 -1 0"/>
  </joint>
  <joint name="finger[1]/flex_joint_from_7_to_8" type="continuous">
    <parent link="finger[1]/flex_link[7]"/>
    <child link="finger[1]/flex_link[8]"/>
    <origin xyz="0.00177777777778 0 0"/>
    <axis xyz="0 -1 0"/>
  </joint>
  <joint name="finger[1]/flex_joint_from_8_to_9" type="continuous">
    <parent link="finger[1]/flex_link[8]"/>
    <child link="finger[1]/flex_link[9]"/>
    <origin xyz="0.00177777777778 0 0"/>
    <axis xyz="0 -1 0"/>
  </joint>
  <joint name="finger[1]/flex_joint_from_prox_to_1" type="continuous">
    <parent link="proximal_1"/>
    <child link="finger[1]/flex_link[1]"/>
    <origin xyz="0.06 0 0.003"/>
    <axis xyz="0 -1 0"/>
  </joint>
  <joint name="finger[1]/flex_joint_from_9_to_dist" type="continuous">
    <parent link="finger[1]/flex_link[9]"/>
    <child link="distal_1"/>
    <origin xyz="-0.00822222222222 0 0.003"/>
    <axis xyz="0 -1 0"/>
  </joint>
  <link name="finger[2]/flex_link[1]">
    <visual>
      <geometry>
        <box size="0.00222222222222 0.014 0.006"/>
      </geometry>
      <material name="dark gray">
        <color rgba="0.2 0.2 .2 1"/>
      </material>
    </visual>
  </link>
  <link name="finger[2]/flex_link[2]">
    <visual>
      <geometry>
        <box size="0.00222222222222 0.014 0.006"/>
      </geometry>
      <material name="dark gray">
        <color rgba="0.2 0.2 .2 1"/>
      </material>
    </visual>
  </link>
  <link name="finger[2]/flex_link[3]">
    <visual>
      <geometry>
        <box size="0.00222222222222 0.014 0.006"/>
      </geometry>
      <material name="dark gray">
        <color rgba="0.2 0.2 .2 1"/>
      </material>
    </visual>
  </link>
  <link name="finger[2]/flex_link[4]">
    <visual>
      <geometry>
        <box size="0.00222222222222 0.014 0.006"/>
      </geometry>
      <material name="dark gray">
        <color rgba="0.2 0.2 .2 1"/>
      </material>
    </visual>
  </link>
  <link name="finger[2]/flex_link[5]">
    <visual>
      <geometry>
        <box size="0.00222222222222 0.014 0.006"/>
      </geometry>
      <material name="dark gray">
        <color rgba="0.2 0.2 .2 1"/>
      </material>
    </visual>
  </link>
  <link name="finger[2]/flex_link[6]">
    <visual>
      <geometry>
        <box size="0.00222222222222 0.014 0.006"/>
      </geometry>
      <material name="dark gray">
        <color rgba="0.2 0.2 .2 1"/>
      </material>
    </visual>
  </link>
  <link name="finger[2]/flex_link[7]">
    <visual>
      <geometry>
        <box size="0.00222222222222 0.014 0.006"/>
      </geometry>
      <material name="dark gray">
        <color rgba="0.2 0.2 .2 1"/>
      </material>
    </visual>
  </link>
  <link name="finger[2]/flex_link[8]">
    <visual>
      <geometry>
        <box size="0.00222222222222 0.014 0.006"/>
      </geometry>
      <material name="dark gray">
        <color rgba="0.2 0.2 .2 1"/>
      </material>
    </visual>
  </link>
  <link name="finger[2]/flex_link[9]">
    <visual>
      <geometry>
        <box size="0.00222222222222 0.014 0.006"/>
      </geometry>
      <material name="dark gray">
        <color rgba="0.2 0.2 .2 1"/>
      </material>
    </visual>
  </link>
  <joint name="finger[2]/flex_joint_from_1_to_2" type="continuous">
    <parent link="finger[2]/flex_link[1]"/>
    <child link="finger[2]/flex_link[2]"/>
    <origin xyz="0.00177777777778 0 0"/>
    <axis xyz="0 -1 0"/>
  </joint>
  <joint name="finger[2]/flex_joint_from_2_to_3" type="continuous">
    <parent link="finger[2]/flex_link[2]"/>
    <child link="finger[2]/flex_link[3]"/>
    <origin xyz="0.00177777777778 0 0"/>
    <axis xyz="0 -1 0"/>
  </joint>
  <joint name="finger[2]/flex_joint_from_3_to_4" type="continuous">
    <parent link="finger[2]/flex_link[3]"/>
    <child link="finger[2]/flex_link[4]"/>
    <origin xyz="0.00177777777778 0 0"/>
    <axis xyz="0 -1 0"/>
  </joint>
  <joint name="finger[2]/flex_joint_from_4_to_5" type="continuous">
    <parent link="finger[2]/flex_link[4]"/>
    <child link="finger[2]/flex_link[5]"/>
    <origin xyz="0.00177777777778 0 0"/>
    <axis xyz="0 -1 0"/>
  </joint>
  <joint name="finger[2]/flex_joint_from_5_to_6" type="continuous">
    <parent link="finger[2]/flex_link[5]"/>
    <child link="finger[2]/flex_link[6]"/>
    <origin xyz="0.00177777777778 0 0"/>
    <axis xyz="0 -1 0"/>
  </joint>
  <joint name="finger[2]/flex_joint_from_6_to_7" type="continuous">
    <parent link="finger[2]/flex_link[6]"/>
    <child link="finger[2]/flex_link[7]"/>
    <origin xyz="0.00177777777778 0 0"/>
    <axis xyz="0 -1 0"/>
  </joint>
  <joint name="finger[2]/flex_joint_from_7_to_8" type="continuous">
    <parent link="finger[2]/flex_link[7]"/>
    <child link="finger[2]/flex_link[8]"/>
    <origin xyz="0.00177777777778 0 0"/>
    <axis xyz="0 -1 0"/>
  </joint>
  <joint name="finger[2]/flex_joint_from_8_to_9" type="continuous">
    <parent link="finger[2]/flex_link[8]"/>
    <child link="finger[2]/flex_link[9]"/>
    <origin xyz="0.00177777777778 0 0"/>
    <axis xyz="0 -1 0"/>
  </joint>
  <joint name="finger[2]/flex_joint_from_prox_to_1" type="continuous">
    <parent link="proximal_2"/>
    <child link="finger[2]/flex_link[1]"/>
    <origin xyz="0.06 0 0.003"/>
    <axis xyz="0 -1 0"/>
  </joint>
  <joint name="finger[2]/flex_joint_from_9_to_dist" type="continuous">
    <parent link="finger[2]/flex_link[9]"/>
    <child link="distal_2"/>
    <origin xyz="-0.00822222222222 0 0.003"/>
    <axis xyz="0 -1 0"/>
  </joint>
  <link name="finger[3]/flex_link[1]">
    <visual>
      <geometry>
        <box size="0.00222222222222 0.014 0.006"/>
      </geometry>
      <material name="dark gray">
        <color rgba="0.2 0.2 .2 1"/>
      </material>
    </visual>
  </link>
  <link name="finger[3]/flex_link[2]">
    <visual>
      <geometry>
        <box size="0.00222222222222 0.014 0.006"/>
      </geometry>
      <material name="dark gray">
        <color rgba="0.2 0.2 .2 1"/>
      </material>
    </visual>
  </link>
  <link name="finger[3]/flex_link[3]">
    <visual>
      <geometry>
        <box size="0.00222222222222 0.014 0.006"/>
      </geometry>
      <material name="dark gray">
        <color rgba="0.2 0.2 .2 1"/>
      </material>
    </visual>
  </link>
  <link name="finger[3]/flex_link[4]">
    <visual>
      <geometry>
        <box size="0.00222222222222 0.014 0.006"/>
      </geometry>
      <material name="dark gray">
        <color rgba="0.2 0.2 .2 1"/>
      </material>
    </visual>
  </link>
  <link name="finger[3]/flex_link[5]">
    <visual>
      <geometry>
        <box size="0.00222222222222 0.014 0.006"/>
      </geometry>
      <material name="dark gray">
        <color rgba="0.2 0.2 .2 1"/>
      </material>
    </visual>
  </link>
  <link name="finger[3]/flex_link[6]">
    <visual>
      <geometry>
        <box size="0.00222222222222 0.014 0.006"/>
      </geometry>
      <material name="dark gray">
        <color rgba="0.2 0.2 .2 1"/>
      </material>
    </visual>
  </link>
  <link name="finger[3]/flex_link[7]">
    <visual>
      <geometry>
        <box size="0.00222222222222 0.014 0.006"/>
      </geometry>
      <material name="dark gray">
        <color rgba="0.2 0.2 .2 1"/>
      </material>
    </visual>
  </link>
  <link name="finger[3]/flex_link[8]">
    <visual>
      <geometry>
        <box size="0.00222222222222 0.014 0.006"/>
      </geometry>
      <material name="dark gray">
        <color rgba="0.2 0.2 .2 1"/>
      </material>
    </visual>
  </link>
  <link name="finger[3]/flex_link[9]">
    <visual>
      <geometry>
        <box size="0.00222222222222 0.014 0.006"/>
      </geometry>
      <material name="dark gray">
        <color rgba="0.2 0.2 .2 1"/>
      </material>
    </visual>
  </link>
  <joint name="finger[3]/flex_joint_from_1_to_2" type="continuous">
    <parent link="finger[3]/flex_link[1]"/>
    <child link="finger[3]/flex_link[2]"/>
    <origin xyz="0.00177777777778 0 0"/>
    <axis xyz="0 -1 0"/>
  </joint>
  <joint name="finger[3]/flex_joint_from_2_to_3" type="continuous">
    <parent link="finger[3]/flex_link[2]"/>
    <child link="finger[3]/flex_link[3]"/>
    <origin xyz="0.00177777777778 0 0"/>
    <axis xyz="0 -1 0"/>
  </joint>
  <joint name="finger[3]/flex_joint_from_3_to_4" type="continuous">
    <parent link="finger[3]/flex_link[3]"/>
    <child link="finger[3]/flex_link[4]"/>
    <origin xyz="0.00177777777778 0 0"/>
    <axis xyz="0 -1 0"/>
  </joint>
  <joint name="finger[3]/flex_joint_from_4_to_5" type="continuous">
    <parent link="finger[3]/flex_link[4]"/>
    <child link="finger[3]/flex_link[5]"/>
    <origin xyz="0.00177777777778 0 0"/>
    <axis xyz="0 -1 0"/>
  </joint>
  <joint name="finger[3]/flex_joint_from_5_to_6" type="continuous">
    <parent link="finger[3]/flex_link[5]"/>
    <child link="finger[3]/flex_link[6]"/>
    <origin xyz="0.00177777777778 0 0"/>
    <axis xyz="0 -1 0"/>
  </joint>
  <joint name="finger[3]/flex_joint_from_6_to_7" type="continuous">
    <parent link="finger[3]/flex_link[6]"/>
    <child link="finger[3]/flex_link[7]"/>
    <origin xyz="0.00177777777778 0 0"/>
    <axis xyz="0 -1 0"/>
  </joint>
  <joint name="finger[3]/flex_joint_from_7_to_8" type="continuous">
    <parent link="finger[3]/flex_link[7]"/>
    <child link="finger[3]/flex_link[8]"/>
    <origin xyz="0.00177777777778 0 0"/>
    <axis xyz="0 -1 0"/>
  </joint>
  <joint name="finger[3]/flex_joint_from_8_to_9" type="continuous">
    <parent link="finger[3]/flex_link[8]"/>
    <child link="finger[3]/flex_link[9]"/>
    <origin xyz="0.00177777777778 0 0"/>
    <axis xyz="0 -1 0"/>
  </joint>
  <joint name="finger[3]/flex_joint_from_prox_to_1" type="continuous">
    <parent link="proximal_3"/>
    <child link="finger[3]/flex_link[1]"/>
    <origin xyz="0.06 0 0.003"/>
    <axis xyz="0 -1 0"/>
  </joint>
  <joint name="finger[3]/flex_joint_from_9_to_dist" type="continuous">
    <parent link="finger[3]/flex_link[9]"/>
    <child link="distal_3"/>
    <origin xyz="-0.00822222222222 0 0.003"/>
    <axis xyz="0 -1 0"/>
  </joint>
  <!-- ################ ################ ################ ################ ################ ################ -->
  <!-- ################ THE SECTION CREATED BY SOLIDWORKS EXPORTER, CUT AND PASTE THIS IN HERE ################ -->
  <!-- ################ YOU CAN ALTER THE COLORS FROM HERE ################ -->
  <!-- ################ COMMENT OUT ALL dist*_joint PIECES OF THIS URDF SO THE FLEX JOINTS CAN LINK UP ################ -->
  <!-- ################ ################ ################ ################ ################ ################ -->
  <link name="base_link">
    <visual>
      <origin rpy="0 0 0" xyz="0 0 0"/>
      <geometry>
        <mesh filename="package://rhr_visualization/meshes/base_link.STL"/>
      </geometry>
      <material name="">
        <color rgba="0.22 0.22 0.22 1"/>
      </material>
    </visual>
  </link>
  <link name="pad">
    <visual>
      <origin rpy="0 0 0" xyz="0 0 0"/>
      <geometry>
        <mesh filename="package://rhr_visualization/meshes/pad.STL"/>
      </geometry>
      <material name="">
        <color rgba="0.2 0.2 .2 1"/>
      </material>
    </visual>
  </link>
  <joint name="pad_joint" type="fixed">
    <origin rpy="0 0 0" xyz="0 0 0"/>
    <parent link="base_link"/>
    <child link="pad"/>
    <axis xyz="0 0 0"/>
  </joint>
  <link name="swivel_1">
    <visual>
      <origin rpy="0 0 0" xyz="0 0 0"/>
      <geometry>
        <mesh filename="package://rhr_visualization/meshes/swivel_1.STL"/>
      </geometry>
      <material name="">
        <color rgba="0.22 0.22 0.22 1"/>
      </material>
    </visual>
  </link>
  <joint name="preshape_1" type="continuous">
    <origin rpy="6.75550818663469E-16 1.97993848419069E-16 -2.77555756156289E-16" xyz="0.0503973683071414 -0.026 0.063"/>
    <parent link="base_link"/>
    <child link="swivel_1"/>
    <axis xyz="0 0 -1"/>
  </joint>
  <link name="proximal_1">
    <visual>
      <origin rpy="0 0 0" xyz="0 0 0"/>
      <geometry>
        <mesh filename="package://rhr_visualization/meshes/proximal_1.STL"/>
      </geometry>
      <material name="">
        <color rgba="0.35 0.35 0.35 1"/>
      </material>
    </visual>
  </link>
  <joint name="proximal_joint_1" type="continuous">
    <origin rpy="-6.20039667432211E-16 2.40507565059625E-17 2.22044604925031E-16" xyz="0.01 0 0.0186"/>
    <parent link="swivel_1"/>
    <child link="proximal_1"/>
    <axis xyz="0 -1 0"/>
  </joint>
  <link name="proximal_pad_1">
    <visual>
      <origin rpy="0 0 0" xyz="0 0 0"/>
      <geometry>
        <mesh filename="package://rhr_visualization/meshes/proximal_pad_1.STL"/>
      </geometry>
      <material name="">
        <color rgba="0.2 0.2 .2 1"/>
      </material>
    </visual>
  </link>
  <joint name="proximal_1_pad_joint" type="fixed">
    <origin rpy="0 0 0" xyz="0 0 0"/>
    <parent link="proximal_1"/>
    <child link="proximal_pad_1"/>
    <axis xyz="0 0 0"/>
  </joint>
  <link name="distal_1">
    <visual>
      <origin rpy="0 0 0" xyz="0 0 0"/>
      <geometry>
        <mesh filename="package://rhr_visualization/meshes/distal_1.STL"/>
      </geometry>
      <material name="">
        <color rgba="0.35 0.35 0.35 1"/>
      </material>
    </visual>
  </link>
  <!--   <joint
    name="distal_joint_1"
    type="continuous">
    <origin
      xyz="0.0760000000000001 0 0.0025"
      rpy="0 0 0" />
    <parent
      link="proximal_1" />
    <child
      link="distal_1" />
    <axis
      xyz="0 -1 0" />
  </joint> -->
  <link name="distal_pad_1">
    <visual>
      <origin rpy="0 0 0" xyz="0 0 0"/>
      <geometry>
        <mesh filename="package://rhr_visualization/meshes/distal_pad_1.STL"/>
      </geometry>
      <material name="">
        <color rgba="0.2 0.2 .2 1"/>
      </material>
    </visual>
  </link>
  <joint name="distal_1_pad_joint" type="fixed">
    <origin rpy="0 0 0" xyz="0 0 0"/>
    <parent link="distal_1"/>
    <child link="distal_pad_1"/>
    <axis xyz="0 0 0"/>
  </joint>
  <link name="swivel_2">
    <visual>
      <origin rpy="0 0 0" xyz="0 0 0"/>
      <geometry>
        <mesh filename="package://rhr_visualization/meshes/swivel_2.STL"/>
      </geometry>
      <material name="">
        <color rgba="0.22 0.22 0.22 1"/>
      </material>
    </visual>
  </link>
  <joint name="preshape_2" type="continuous">
    <origin rpy="1.22459340959228E-15 -7.33448407631817E-16 -1.66533453693773E-16" xyz="0.0503973683071413 0.0259999999999999 0.063"/>
    <parent link="base_link"/>
    <child link="swivel_2"/>
    <axis xyz="0 0 -1"/>
  </joint>
  <link name="proximal_2">
    <visual>
      <origin rpy="0 0 0" xyz="0 0 0"/>
      <geometry>
        <mesh filename="package://rhr_visualization/meshes/proximal_2.STL"/>
      </geometry>
      <material name="">
        <color rgba="0.35 0.35 0.35 1"/>
      </material>
    </visual>
  </link>
  <joint name="proximal_joint_2" type="continuous">
    <origin rpy="-1.16908225836102E-15 9.55493012556849E-16 1.11022302462515E-16" xyz="0.01 0 0.0186"/>
    <parent link="swivel_2"/>
    <child link="proximal_2"/>
    <axis xyz="0 -1 0"/>
  </joint>
  <link name="proximal_pad_2">
    <visual>
      <origin rpy="0 0 0" xyz="0 0 0"/>
      <geometry>
        <mesh filename="package://rhr_visualization/meshes/proximal_pad_2.STL"/>
      </geometry>
      <material name="">
        <color rgba="0.2 0.2 .2 1"/>
      </material>
    </visual>
  </link>
  <joint name="proximal_2_pad_joint" type="fixed">
    <origin rpy="0 0 0" xyz="0 0 0"/>
    <parent link="proximal_2"/>
    <child link="proximal_pad_2"/>
    <axis xyz="0 0 0"/>
  </joint>
  <link name="distal_2">
    <visual>
      <origin rpy="0 0 0" xyz="0 0 0"/>
      <geometry>
        <mesh filename="package://rhr_visualization/meshes/distal_2.STL"/>
      </geometry>
      <material name="">
        <color rgba="0.35 0.35 0.35 1"/>
      </material>
    </visual>
  </link>
  <!--   <joint
    name="distal_joint_2"
    type="continuous">
    <origin
      xyz="0.076 0 0.0025"
      rpy="0 0 0" />
    <parent
      link="proximal_2" />
    <child
      link="distal_2" />
    <axis
      xyz="0 -1 0" />
  </joint> -->
  <link name="distal_pad_2">
    <visual>
      <origin rpy="0 0 0" xyz="0 0 0"/>
      <geometry>
        <mesh filename="package://rhr_visualization/meshes/distal_pad_2.STL"/>
      </geometry>
      <material name="">
        <color rgba="0.2 0.2 .2 1"/>
      </material>
    </visual>
  </link>
  <joint name="distal_2_pad_joint" type="fixed">
    <origin rpy="0 0 0" xyz="0 0 0"/>
    <parent link="distal_2"/>
    <child link="distal_pad_2"/>
    <axis xyz="0 0 0"/>
  </joint>
  <link name="proximal_3">
    <visual>
      <origin rpy="0 0 0" xyz="0 0 0"/>
      <geometry>
        <mesh filename="package://rhr_visualization/meshes/proximal_3.STL"/>
      </geometry>
      <material name="">
        <color rgba="0.35 0.35 0.35 1"/>
      </material>
    </visual>
  </link>
  <joint name="proximal_joint_3" type="continuous">
    <origin rpy="-5.55111512312578E-17 -2.22044604925031E-16 3.14159265358979" xyz="-0.03 0 0.0816000000000001"/>
    <parent link="base_link"/>
    <child link="proximal_3"/>
    <axis xyz="0 -1 0"/>
  </joint>
  <link name="proximal_pad_3">
    <visual>
      <origin rpy="0 0 0" xyz="0 0 0"/>
      <geometry>
        <mesh filename="package://rhr_visualization/meshes/proximal_pad_3.STL"/>
      </geometry>
      <material name="">
        <color rgba="0.2 0.2 .2 1"/>
      </material>
    </visual>
  </link>
  <joint name="proximal_3_pad_joint" type="continuous">
    <origin rpy="-8.12078539014657E-108 0 0" xyz="0 0 0"/>
    <parent link="proximal_3"/>
    <child link="proximal_pad_3"/>
    <axis xyz="0 -1 0"/>
  </joint>
  <link name="distal_3">
    <visual>
      <origin rpy="0 0 0" xyz="0 0 0"/>
      <geometry>
        <mesh filename="package://rhr_visualization/meshes/distal_3.STL"/>
      </geometry>
      <material name="">
        <color rgba="0.35 0.35 0.35 1"/>
      </material>
    </visual>
  </link>
  <!--   <joint
    name="distal_joint_3"
    type="continuous">
    <origin
      xyz="0.0760000000000001 0 0.0025"
      rpy="0 0 0" />
    <parent
      link="proximal_3" />
    <child
      link="distal_3" />
    <axis
      xyz="0 -1 0" />
  </joint> -->
  <link name="distal_pad_3">
    <visual>
      <origin rpy="0 0 0" xyz="0 0 0"/>
      <geometry>
        <mesh filename="package://rhr_visualization/meshes/distal_pad_3.STL"/>
      </geometry>
      <material name="">
        <color rgba="0.2 0.2 .2 1"/>
      </material>
    </visual>
  </link>
  <joint name="distal_3_pad_joint" type="fixed">
    <origin rpy="0 0 0" xyz="0 0 0"/>
    <parent link="distal_3"/>
    <child link="distal_pad_3"/>
    <axis xyz="0 0 0"/>
  </joint>
  <!-- ################ ################ ################ ################ ################ ################ -->
  <!-- ################ THIS SECTION LINKS THE MARKERS (TACTILE DATA) TO THE CAD MESH ################ -->
  <!-- ################ COPY AND PASTE THIS FROM urdf/homemade_marker_portion_urdf  ################ -->
  <!-- ################ ################ ################ ################ ################ ################ -->
  <joint name="base_tactile_joint" type="fixed">
    <origin rpy="0 0 1.57075" xyz="0 0 0"/>
    <parent link="base_link"/>
    <child link="base_tactile"/>
  </joint>
  <link name="base_tactile"/>
  <link name="proximal_1_tactile"/>
  <joint name="proximal_1_tactile_joint" type="fixed">
    <origin rpy="0 0 0" xyz="0 0 0"/>
    <parent link="proximal_1"/>
    <child link="proximal_1_tactile"/>
  </joint>
  <joint name="proximal_2_tactile_joint" type="fixed">
    <origin rpy="0 0 0" xyz="0 0 0"/>
    <parent link="proximal_2"/>
    <child link="proximal_2_tactile"/>
  </joint>
  <link name="proximal_2_tactile"/>
  <joint name="proximal_3_tactile_joint" type="fixed">
    <origin rpy="0 0 0" xyz="0 0 0"/>
    <parent link="proximal_3"/>
    <child link="proximal_3_tactile"/>
  </joint>
  <link name="proximal_3_tactile"/>
  <joint name="distal_1_tactile_joint" type="fixed">
    <origin rpy="0 0 0" xyz="0 0 0"/>
    <parent link="distal_1"/>
    <child link="distal_1_tactile"/>
  </joint>
  <link name="distal_1_tactile"/>
  <joint name="distal_2_tactile_joint" type="fixed">
    <origin rpy="0 0 0" xyz="0 0 0"/>
    <parent link="distal_2"/>
    <child link="distal_2_tactile"/>
  </joint>
  <link name="distal_2_tactile"/>
  <joint name="distal_3_tactile_joint" type="fixed">
    <origin rpy="0 0 0" xyz="0 0 0"/>
    <parent link="distal_3"/>
    <child link="distal_3_tactile"/>
  </joint>
  <link name="distal_3_tactile"/>
</robot>

